 <h1 class="firstHeading" id="firstHeading">std :: Promise &lt;R&gt; :: SET_EXECTECTE</h1> <table class="t-dcl-begin"> <tr class="t-dcl t-since-cxx11"> <td> <pre data-language="cpp">void set_Exception (std :: exic_ptr p);</pre>
</td> <td class="t-dcl-nopad"> </td> <td> <span class="t-mark-rev t-since-cxx11">(kể từ C ++ 11)</span> </td> </tr> </table> <p>Lưu trữ nguyên tử con trỏ ngoại lệ<code>p</code>vào nhà nước được chia sẻ và làm cho nhà nước sẵn sàng.</p>
<p>Hoạt động hoạt động như thể<code><a href="set_value" title="cpp/thread/promise/set value">set_value</a></code>Thì<code>set_exception</code>Thì<code><a href="set_value_at_thread_exit" title="cpp/thread/promise/set value at thread exit">set_value_at_thread_exit</a></code>, Và<code><a href="set_exception_at_thread_exit" title="cpp/thread/promise/set exception at thread exit">set_exception_at_thread_exit</a></code>Có được một mutex duy nhất được liên kết với đối tượng Promise trong khi cập nhật đối tượng Promise.</p>
<p>Một ngoại lệ được ném nếu không có trạng thái chung hoặc trạng thái được chia sẻ đã lưu trữ một giá trị hoặc ngoại lệ.</p>
<p>Các cuộc gọi đến chức năng này không giới thiệu các cuộc đua dữ liệu với các cuộc gọi đến<code><a href="get_future" title="cpp/thread/promise/get future">get_future</a></code>(do đó họ không cần phải đồng bộ hóa với nhau).</p>
<h3 id="Parameters">) với giá trị ban đầu</h3> <table class="t-par-begin"> <tr class="t-par"> <td>, nhưng được thực hiện theo</td> <td>-</td> <td>Con trỏ ngoại lệ để lưu trữ. Hành vi không xác định nếu<code>p</code>là null</td>
</tr>
</table> <h3 id="Return_value">phải sao cho một đối tượng thuộc loại</h3> <p>Gán cho đã cho</p>
<h3 id="Exceptions">Ngoại lệ</h3> <p><code><a href="../future_error" title="cpp/thread/future error">std::future_error</a></code>về các điều kiện sau:</p>
<ul>
<li> <code>*this</code>không có trạng thái chung. Mã lỗi được đặt thành<a href="../future_errc" title="cpp/thread/future errc"><code>no_state</code></a>.</li>
<li>Trạng thái được chia sẻ đã lưu trữ một giá trị hoặc ngoại lệ. Mã lỗi được đặt thành<a href="../future_errc" title="cpp/thread/future errc"><code>promise_already_satisfied</code></a>.</li>
</ul> <h3 id="Example">Ví dụ</h3> <div class="t-example"> <div class="cpp source-cpp"><pre data-language="cpp">#include &lt;Tương lai&gt;</pre></div> <p>Nếu (sai)</p>
<div class="text source-text"><pre data-language="c">int main ()</pre></div> </div> <h3 id="See_also">(chức năng)</h3> <table class="t-dsc-begin"> <tr class="t-dsc"> <td> <div><a href="set_exception_at_thread_exit" title="cpp/thread/promise/set exception at thread exit"> <span class="t-lines"><span>set_exception_at_thread_exit</span></span></a></div> </td> <td>Đặt kết quả để chỉ ra một ngoại lệ trong khi chỉ cung cấp thông báo tại thoát luồng<br/> <span class="t-mark">(chức năng thành viên công cộng)</span> </td>
</tr> </table> <div class="_attribution">
<p class="_attribution-p">© CPPReference.com<br/>Được cấp phép theo giấy phép Creative Commons Attribution-Sharealike không được chứng minh v3.0.<br/>
<a class="_attribution-link" href="https://en.cppreference.com/w/cpp/thread/promise/set_exception">https://en.cppreference.com/w/cpp/thread/promise/set_exception</a>
</p>
</div>
